<mujoco model="ur5_hand_robot">
     <body name="ur5_arm_base_link" pos="0 0 0.003">
        <inertial pos="0 0 0" quat="0.5 0.5 -0.5 0.5" mass="4" diaginertia="0.01125 0.00610633 0.00610633" />
        <geom type="mesh" rgba="0.7 0.7 0.7 1" mesh="base" /> 
        <body name="ur5_arm_shoulder_link" pos="0 0 0.0862" >
            <inertial pos="0 0 0" mass="3.7" diaginertia="0.0102675 0.0102675 0.00666" />
            <joint name="ra_shoulder_pan_joint" pos="0 0 0" axis="0 0 1" limited="false" range="-3.14159 3.14159" />
            <geom type="mesh" rgba="0.7 0.7 0.7 1"  mesh="shoulder" />
            <!-- <body name="ur5_arm_upper_arm_link" pos="0 0.13585 0" quat="1.0 0 0. 0"> -->
            <body name="ur5_arm_upper_arm_link" pos="0 0.13585 0" quat="0.707107 0 0.707107 0">
                <inertial pos="0 0 0.28" mass="8.393" diaginertia="0.226891 0.226891 0.0151074" />
                <joint name="ra_shoulder_lift_joint" pos="0 0 0" axis="0 1 0" limited="false" range="-3.14159 3.14159" /> <!--Range= -3.14159 3.14159-->
                <geom type="mesh" rgba="0.7 0.7 0.7 1" mesh="upperarm" />
                <!-- <body name="ur5_arm_forearm_link" pos="0 -0.1197 0.425" quat="0.707107 0 -0.707107 0"> -->
                <body name="ur5_arm_forearm_link" pos="0 -0.1197 0.425">
                    <inertial pos="0 0 0.25" mass="2.275" diaginertia="0.0494433 0.0494433 0.004095" />
                    <joint name="ra_elbow_joint" pos="0 0 0" axis="0 1 0" limited="false" range="-3.14159 3.14159" />
                    <geom type="mesh"  rgba="0.7 0.7 0.7 1" mesh="forearm_ur" />
                    <!-- <body name="ur5_arm_wrist_1_link" pos="0 0 0.39225" quat="0.707107 0 -0.707107 0"> -->
                    <body name="ur5_arm_wrist_1_link" pos="0 0 0.39225" quat="0.707107 0 0.707107 0">
                        <inertial pos="0 0 0" quat="0.5 0.5 -0.5 0.5" mass="1.219" diaginertia="0.21942 0.111173 0.111173" />
                        <joint name="ra_wrist_1_joint" pos="0 0 0" axis="0 1 0" limited="false" range="-3.14159 3.14159" />
                        <geom type="mesh" rgba="0.7 0.7 0.7 1"  mesh="wrist1" />
                        <!-- <body name="ur5_arm_wrist_2_link" pos="0 0.093 0" quat="0.707107 0 0 -0.707107"> -->
                        <body name="ur5_arm_wrist_2_link" pos="0 0.093 0">
                            <inertial pos="0 0 0" quat="0.5 0.5 -0.5 0.5" mass="1.219" diaginertia="0.21942 0.111173 0.111173" />
                            <joint name="ra_wrist_2_joint" pos="0 0 0" axis="0 0 1" limited="false" range="-3.14159 3.14159" />
                            <geom type="mesh"  rgba="0.7 0.7 0.7 1" mesh="wrist2" />
                            <!-- <body name="ur5_arm_wrist_3_link" pos="0 0 0.09465" quat="0.707107 0 0.707107 0"> -->
                            <body name="ur5_arm_wrist_3_link" pos="0 0 0.09465" >
                                <inertial pos="1.10016e-10 0.136364 4.88137e-05" quat="0.499969 0.500031 -0.500031 0.499969" mass="2.1389" diaginertia="0.0441119 0.0274263 0.0218065" />
                                <joint name="ra_wrist_3_joint" pos="0 0 0" axis="0 1 0" limited="false" range="-3.14159 3.14159" />
                                <geom type="mesh" rgba="0.7 0.7 0.7 1"  mesh="wrist3" />
                                <!-- <geom size="0.005 0.005 0.005" pos="-1.7949e-11 0.0723 0" quat="0.707107 0 0 0.707107" type="box" rgba="1 0 0 1"/> -->
                                <!-- <geom pos="0 0.0823 0" quat="0.500199 -0.499801 0.499801 0.500199" type="mesh" contype="0" conaffinity="0" group="1" rgba="0 0 0 1" mesh="robotiq_fts300" /> -->
                                <!-- <geom pos="0 0.0823 0" quat="0.500199 -0.499801 0.499801 0.500199" rgba="0 0 0 1" type="mesh" mesh="robotiq_fts300" /> -->
                                
                                <body name="ee_link" pos="0 0.0823 0" quat="0.707107 0 0 0.707107">
                                    <inertial pos="0 0 0" mass="0.001" diaginertia="1.66667e-08 1.66667e-08 1.66667e-08" />
                                    <geom size="0.005 0.005 0.005" pos="0 0 0" type="box" />
                                        <body name="ur5_arm_to_hand" euler="1.57079632679 1.57079632679 0">
                                            <inertial pos="-0.01 0 0" mass="0.001" diaginertia="1.66667e-08 1.66667e-08 1.66667e-08" />
                                            <geom size="0.005 0.005 0.005" pos="0.012 0.0 0.0" type="box"  />
                                            <include file="sr_hand_e_plus_model.xml" />
                                        </body>
                                    <body name="ur5_tool0" pos="0 0.0922 0" quat="0.707107 -0.707107 0 0">
                                        <inertial pos="0 0.0922 0" quat="0.707107 -0.707107 0 0" mass="0" diaginertia="0 0 0" />
                                    </body>
                                </body>
                                                             
                                <!-- add gripper here -->
                                
                            </body>
                        </body>
                    </body>
                </body>
            </body>
            <body name="ur5_base" pos="0 0 0" quat="1.7949e-09 0 0 -1">
                <inertial pos="0 0 0" quat="1.7949e-09 0 0 -1" mass="0" diaginertia="0 0 0" />
            </body>
        </body>

    </body>


</mujoco>